<?xml version="1.0"?>
<robot xmlns:xacro="http://www.ros.org/wiki/xacro" name="robot">

    <!-- Include materials file -->
    <xacro:include filename="materials.xacro" />
    <xacro:property name="PI" value="3.141592653589793"/>

    <!-- World link must be defined before being referenced -->
    <link name="world"/>

    <link name="base_link">
        <visual>
            <origin xyz="0 0 0" rpy="0 0 0"/>
            <geometry>
                <mesh filename="package://parm_urdf/meshes/base_link.stl" scale="0.001 0.001 0.001"/>
            </geometry>
            <material name="silver"/>
        </visual>
        <collision>
            <origin xyz="0 0 0" rpy="0 0 0"/>
            <geometry>
                <mesh filename="package://parm_urdf/meshes/base_link.stl" scale="0.001 0.001 0.001"/>
            </geometry>
        </collision>
    </link>

    <link name="ax1_ax2_link_1">
        <visual>
            <origin xyz="0.0 0.0 0.0" rpy="0 0 0"/>
            <geometry>
                <mesh filename="package://parm_urdf/meshes/ax1_ax2_link_1.stl" scale="0.001 0.001 0.001"/>
            </geometry>
            <material name="silver"/>
        </visual>
        <collision>
            <origin xyz="0.0 0.0 0.0" rpy="0 0 0"/>
            <geometry>
                <mesh filename="package://parm_urdf/meshes/ax1_ax2_link_1.stl" scale="0.001 0.001 0.001"/>
            </geometry>
        </collision>
    </link>

    <link name="ax2_ax3_link_1">
        <visual>
            <origin xyz="0.0 0.0 -0.2" rpy="0 0 0"/>
            <geometry>
                <mesh filename="package://parm_urdf/meshes/ax2_ax3_link_1.stl" scale="0.001 0.001 0.001"/>
            </geometry>
            <material name="silver"/>
        </visual>
        <collision>
            <origin xyz="0.0 0.0 -0.2" rpy="0 0 0"/>
            <geometry>
                <mesh filename="package://parm_urdf/meshes/ax2_ax3_link_1.stl" scale="0.001 0.001 0.001"/>
            </geometry>
        </collision>
    </link>

    <link name="ax3_ax4_link_1">
        <visual>
            <origin xyz="0.26 0.0 -0.22" rpy="0 0 0"/>
            <geometry>
                <mesh filename="package://parm_urdf/meshes/ax3_ax4_link_1.stl" scale="0.001 0.001 0.001"/>
            </geometry>
            <material name="silver"/>
        </visual>
        <collision>
            <origin xyz="0.26 0.0 -0.22" rpy="0 0 0"/>
            <geometry>
                <mesh filename="package://parm_urdf/meshes/ax3_ax4_link_1.stl" scale="0.001 0.001 0.001"/>
            </geometry>
        </collision>
    </link>

    <link name="ax4_ax5_link_1">
        <visual>
            <origin xyz="0.03 0.0 0.03" rpy="0 0 ${PI/2}"/>
            <geometry>
                <mesh filename="package://parm_urdf/meshes/ax4_ax5_link_1.stl" scale="0.001 0.001 0.001"/>
            </geometry>
            <material name="silver"/>
        </visual>
        <collision>
            <origin xyz="0.03 0.0 0.03" rpy="0 0 ${PI/2}"/>
            <geometry>
                <mesh filename="package://parm_urdf/meshes/ax4_ax5_link_1.stl" scale="0.001 0.001 0.001"/>
            </geometry>
        </collision>
    </link>

    <link name="ax4_ax5_link_2">
        <visual>
            <origin xyz="0.18 0.0 -0.028" rpy="${-PI/2} 0 0"/>
            <geometry>
                <mesh filename="package://parm_urdf/meshes/ax4_ax5_link_2.stl" scale="0.001 0.001 0.001"/>
            </geometry>
            <material name="silver"/>
        </visual>
        <collision>
            <origin xyz="0.18 0.0 -0.028" rpy="${-PI/2} 0 0"/>
            <geometry>
                <mesh filename="package://parm_urdf/meshes/ax4_ax5_link_2.stl" scale="0.001 0.001 0.001"/>
            </geometry>
        </collision>
    </link>

    <link name="ax5_ax6_link_1">
        <visual>
            <origin xyz="0.18 0.0 -0.028" rpy="${-PI/2} 0 0"/>
            <geometry>
                <mesh filename="package://parm_urdf/meshes/ax5_ax6_link_1.stl" scale="0.001 0.001 0.001"/>
            </geometry>
            <material name="silver"/>
        </visual>
        <collision>
            <origin xyz="0.18 0.0 -0.028" rpy="${-PI/2} 0 0"/>
            <geometry>
                <mesh filename="package://parm_urdf/meshes/ax5_ax6_link_1.stl" scale="0.001 0.001 0.001"/>
            </geometry>
        </collision>
    </link>

    <link name="ax6_gripper_link_1">
        <visual>
            <origin xyz="0.34 0.0 -0.025" rpy="${-PI/2} 0 0"/>
            <geometry>
                <mesh filename="package://parm_urdf/meshes/ax6_gripper_link_1.stl" scale="0.001 0.001 0.001"/>
            </geometry>
            <material name="silver"/>
        </visual>
        <collision>
            <origin xyz="0.34 0.0 -0.025" rpy="${-PI/2} 0 0"/>
            <geometry>
                <mesh filename="package://parm_urdf/meshes/ax6_gripper_link_1.stl" scale="0.001 0.001 0.001"/>
            </geometry>
        </collision>
    </link>

    <link name="gripper_link">
        <visual>
            <origin xyz="0.0 0.0 0.076" rpy="0 ${-PI/2} 0"/>
            <geometry>
                <mesh filename="package://parm_urdf/meshes/gripper_link.stl" scale="1 1 1"/>
            </geometry>
            <material name="silver"/>
        </visual>
        <collision>
            <origin xyz="0.0 0.0 0.076" rpy="0 ${-PI/2} 0"/>
            <geometry>
                <mesh filename="package://parm_urdf/meshes/gripper_link.stl" scale="1 1 1"/>
            </geometry>
        </collision>
    </link>

    <link name="gripper_finger_link1">
        <visual>
            <origin xyz="0.0 0.015 0.045" rpy="0 ${-PI/2} 0"/>
            <geometry>
                <mesh filename="package://parm_urdf/meshes/gripper_finger_link1.stl" scale="1 1 1"/>
            </geometry>
            <material name="silver"/>
        </visual>
        <collision>
            <origin xyz="0.0 0.015 0.045" rpy="0 ${-PI/2} 0"/>
            <geometry>
                <mesh filename="package://parm_urdf/meshes/gripper_finger_link1.stl" scale="1 1 1"/>
            </geometry>
        </collision>
    </link>

    <link name="gripper_finger_link2">
        <visual>
            <origin xyz="0.0 0.015 0.045" rpy="0 ${-PI/2} ${PI}"/>
            <geometry>
                <mesh filename="package://parm_urdf/meshes/gripper_finger_link2.stl" scale="1 1 1"/>
            </geometry>
            <material name="silver"/>
        </visual>
        <collision>
            <origin xyz="0.0 0.015 0.045" rpy="0 ${-PI/2} ${PI}"/>
            <geometry>
                <mesh filename="package://parm_urdf/meshes/gripper_finger_link2.stl" scale="1 1 1"/>
            </geometry>
        </collision>
    </link>

    <!-- Joints -->
    <joint name="base_to_world" type="fixed">
        <parent link="world"/>
        <child link="base_link"/>
        <origin xyz="0 0 0" rpy="0 0 0"/>
    </joint>

    <joint name="revolute_1" type="revolute">
        <origin xyz="0.0 0.0 0.0" rpy="0 0 0"/>
        <parent link="base_link"/>
        <child link="ax1_ax2_link_1"/>
        <axis xyz="0.0 0.0 -1.0"/>
        <limit lower="0.0" upper="${2.0*PI}" effort="30" velocity="1.0"/>
    </joint>

    <joint name="revolute_2" type="revolute">
        <origin xyz="0.0 0.0 0.2" rpy="0 0 0"/>
        <parent link="ax1_ax2_link_1"/>
        <child link="ax2_ax3_link_1"/>
        <axis xyz="0.0 1.0 0.0"/>
        <limit lower="0.0" upper="${PI}" effort="30" velocity="1.0"/>
    </joint>

    <joint name="revolute_3" type="revolute">
        <origin xyz="-0.27 0.0 0.01" rpy="0 -0.5 0"/>
        <parent link="ax2_ax3_link_1"/>
        <child link="ax3_ax4_link_1"/>
        <axis xyz="0.0 -1.0 0.0"/>
        <limit lower="0.0" upper="${PI/8.0}" effort="30" velocity="1.0"/>
    </joint>

    <joint name="revolute_4" type="revolute">
        <origin xyz="-0.25 0.0 0.025" rpy="0 0 0"/>
        <parent link="ax3_ax4_link_1"/>
        <child link="ax4_ax5_link_1"/>
        <axis xyz="0.0 1.0 0.0"/>
        <limit lower="0.0" upper="${5.0*PI/4.0}" effort="30" velocity="1.0"/>
    </joint>
    <joint name="fixed_con" type="fixed">
        <origin xyz="0.0 0.0 0.0" rpy="0 0 0"/>
        <parent link="ax4_ax5_link_1"/>
        <child link="ax4_ax5_link_2"/>
    </joint>

    <joint name="revolute_5" type="revolute">
        <origin xyz="0.0 0.0 0.0" rpy="0 0 0"/>
        <parent link="ax4_ax5_link_2"/>
        <child link="ax5_ax6_link_1"/>
        <axis xyz="1.0 0.0 0.0"/>
        <limit lower="0.0" upper="${5.0*PI/4.0}" effort="30" velocity="1.0"/>
    </joint>

    <joint name="revolute_6" type="revolute">
        <origin xyz="-0.16 0.0 0.0" rpy="0 0 0"/>
        <parent link="ax5_ax6_link_1"/>
        <child link="ax6_gripper_link_1"/>
        <axis xyz="0.0 0.0 1.0"/>
        <limit lower="0.0" upper="${5.0*PI/4.0}" effort="30" velocity="1.0"/>
    </joint>
    <joint name="fixed_gripper" type="fixed">
        <origin xyz="0.0 0.0 0.0" rpy="0 0 0"/>
        <parent link="ax6_gripper_link_1"/>
        <child link="gripper_link"/>
    </joint>

    <joint name="prismatic_1" type="prismatic">
        <origin xyz="0.0 0.0 0.067" rpy="0 0 0"/>
        <parent link="gripper_link"/>
        <child link="gripper_finger_link1"/>
        <axis xyz="0.0 1.0 0.0"/>
        <limit lower="0.0" upper="0.05" effort="30" velocity="0.1"/>
    </joint>
    <joint name="prismatic_2" type="prismatic">
        <origin xyz="0.0 0.0 0.067" rpy="0 0 ${PI}"/>
        <parent link="gripper_link"/>
        <child link="gripper_finger_link2"/>
        <axis xyz="0.0 1.0 0.0"/>
        <limit lower="0.0" upper="0.05" effort="30" velocity="0.1"/>
    </joint>

</robot>
