<?xml version="1.0" ?>
<!-- =================================================================================== -->
<!-- |    This document was autogenerated by xacro from Parm.urdf.xacro                | -->
<!-- |    EDITING THIS FILE BY HAND IS NOT RECOMMENDED                                 | -->
<!-- =================================================================================== -->
<robot name="robot">
  <material name="silver">
    <color rgba="0.700 0.700 0.700 1.000"/>
  </material>
  <!-- World link must be defined before being referenced -->
  <link name="world"/>
  <link name="base_link">
    <visual>
      <origin rpy="0 0 0" xyz="0 0 0"/>
      <geometry>
        <mesh filename="package://parm_urdf/meshes/base_link.stl" scale="0.001 0.001 0.001"/>
      </geometry>
      <material name="silver"/>
    </visual>
    <collision>
      <origin rpy="0 0 0" xyz="0 0 0"/>
      <geometry>
        <mesh filename="package://parm_urdf/meshes/base_link.stl" scale="0.001 0.001 0.001"/>
      </geometry>
    </collision>
  </link>
  <link name="ax1_ax2_link_1">
    <visual>
      <origin rpy="0 0 0" xyz="0.0 0.0 0.0"/>
      <geometry>
        <mesh filename="package://parm_urdf/meshes/ax1_ax2_link_1.stl" scale="0.001 0.001 0.001"/>
      </geometry>
      <material name="silver"/>
    </visual>
    <collision>
      <origin rpy="0 0 0" xyz="0.0 0.0 0.0"/>
      <geometry>
        <mesh filename="package://parm_urdf/meshes/ax1_ax2_link_1.stl" scale="0.001 0.001 0.001"/>
      </geometry>
    </collision>
  </link>
  <link name="ax2_ax3_link_1">
    <visual>
      <origin rpy="0 0 0" xyz="0.0 0.0 -0.2017"/>
      <geometry>
        <mesh filename="package://parm_urdf/meshes/ax2_ax3_link_1.stl" scale="0.001 0.001 0.001"/>
      </geometry>
      <material name="silver"/>
    </visual>
    <collision>
      <origin rpy="0 0 0" xyz="0.0 0.0 -0.2017"/>
      <geometry>
        <mesh filename="package://parm_urdf/meshes/ax2_ax3_link_1.stl" scale="0.001 0.001 0.001"/>
      </geometry>
    </collision>
  </link>
  <link name="ax3_ax4_link_1">
    <visual>
      <origin rpy="0 0 0" xyz="0.2695 0.0 -0.218"/>
      <geometry>
        <mesh filename="package://parm_urdf/meshes/ax3_ax4_link_1.stl" scale="0.001 0.001 0.001"/>
      </geometry>
      <material name="silver"/>
    </visual>
    <collision>
      <origin rpy="0 0 0" xyz="0.2695 0.0 -0.218"/>
      <geometry>
        <mesh filename="package://parm_urdf/meshes/ax3_ax4_link_1.stl" scale="0.001 0.001 0.001"/>
      </geometry>
    </collision>
  </link>
  <link name="ax4_ax5_link_1">
    <visual>
      <origin rpy="0 0 1.5707963267948966" xyz="0.0303 0.0 0.03"/>
      <geometry>
        <mesh filename="package://parm_urdf/meshes/ax4_ax5_link_1.stl" scale="0.001 0.001 0.001"/>
      </geometry>
      <material name="silver"/>
    </visual>
    <collision>
      <origin rpy="0 0 1.5707963267948966" xyz="0.0303 0.0 0.03"/>
      <geometry>
        <mesh filename="package://parm_urdf/meshes/ax4_ax5_link_1.stl" scale="0.001 0.001 0.001"/>
      </geometry>
    </collision>
  </link>
  <link name="ax4_ax5_link_2">
    <visual>
      <origin rpy="-1.5707963267948966 0 0" xyz="0.18 0.0 -0.028"/>
      <geometry>
        <mesh filename="package://parm_urdf/meshes/ax4_ax5_link_2.stl" scale="0.001 0.001 0.001"/>
      </geometry>
      <material name="silver"/>
    </visual>
    <collision>
      <origin rpy="-1.5707963267948966 0 0" xyz="0.18 0.0 -0.028"/>
      <geometry>
        <mesh filename="package://parm_urdf/meshes/ax4_ax5_link_2.stl" scale="0.001 0.001 0.001"/>
      </geometry>
    </collision>
  </link>
  <link name="ax5_ax6_link_1">
    <visual>
      <origin rpy="-1.5707963267948966 0 0" xyz="0.18 0.0 -0.0273"/>
      <geometry>
        <mesh filename="package://parm_urdf/meshes/ax5_ax6_link_1.stl" scale="0.001 0.001 0.001"/>
      </geometry>
      <material name="silver"/>
    </visual>
    <collision>
      <origin rpy="-1.5707963267948966 0 0" xyz="0.18 0.0 -0.0273"/>
      <geometry>
        <mesh filename="package://parm_urdf/meshes/ax5_ax6_link_1.stl" scale="0.001 0.001 0.001"/>
      </geometry>
    </collision>
  </link>
  <link name="ax6_gripper_link_1">
    <visual>
      <origin rpy="-1.5707963267948966 0 0" xyz="0.3425 0.0001 -0.025"/>
      <geometry>
        <mesh filename="package://parm_urdf/meshes/ax6_gripper_link_1.stl" scale="0.001 0.001 0.001"/>
      </geometry>
      <material name="silver"/>
    </visual>
    <collision>
      <origin rpy="-1.5707963267948966 0 0" xyz="0.3425 0.0001 -0.025"/>
      <geometry>
        <mesh filename="package://parm_urdf/meshes/ax6_gripper_link_1.stl" scale="0.001 0.001 0.001"/>
      </geometry>
    </collision>
  </link>
  <link name="gripper_link">
    <visual>
      <origin rpy="0 -1.5707963267948966 0" xyz="0.0 0.0 0.077"/>
      <geometry>
        <mesh filename="package://parm_urdf/meshes/gripper_link.stl" scale="1 1 1"/>
      </geometry>
      <material name="silver"/>
    </visual>
    <collision>
      <origin rpy="0 -1.5707963267948966 0" xyz="0.0 0.0 0.077"/>
      <geometry>
        <mesh filename="package://parm_urdf/meshes/gripper_link.stl" scale="1 1 1"/>
      </geometry>
    </collision>
  </link>
  <link name="gripper_finger_link1">
    <visual>
      <origin rpy="0 -1.5707963267948966 0" xyz="0.0 0.015 0.045"/>
      <geometry>
        <mesh filename="package://parm_urdf/meshes/gripper_finger_link1.stl" scale="1 1 1"/>
      </geometry>
      <material name="silver"/>
    </visual>
    <collision>
      <origin rpy="0 -1.5707963267948966 0" xyz="0.0 0.015 0.045"/>
      <geometry>
        <mesh filename="package://parm_urdf/meshes/gripper_finger_link1.stl" scale="1 1 1"/>
      </geometry>
    </collision>
  </link>
  <link name="gripper_finger_link2">
    <visual>
      <origin rpy="0 -1.5707963267948966 3.141592653589793" xyz="0.0 0.015 0.045"/>
      <geometry>
        <mesh filename="package://parm_urdf/meshes/gripper_finger_link2.stl" scale="1 1 1"/>
      </geometry>
      <material name="silver"/>
    </visual>
    <collision>
      <origin rpy="0 -1.5707963267948966 3.141592653589793" xyz="0.0 0.015 0.045"/>
      <geometry>
        <mesh filename="package://parm_urdf/meshes/gripper_finger_link2.stl" scale="1 1 1"/>
      </geometry>
    </collision>
  </link>
  <!-- Joints -->
  <joint name="base_to_world" type="fixed">
    <parent link="world"/>
    <child link="base_link"/>
    <origin rpy="0 0 0" xyz="0 0 0"/>
  </joint>
  <joint name="revolute_1" type="revolute">
    <origin rpy="0 0 0" xyz="0.0 0.0 0.0"/>
    <parent link="base_link"/>
    <child link="ax1_ax2_link_1"/>
    <axis xyz="0.0 0.0 -1.0"/>
    <limit effort="30" lower="0.0" upper="6.283185307179586" velocity="1.01" acceleration="1.01"/>
  </joint>
  <joint name="revolute_2" type="revolute">
    <origin rpy="0 0.7853981633974483 0" xyz="0.0 0.0 0.202"/>
    <parent link="ax1_ax2_link_1"/>
    <child link="ax2_ax3_link_1"/>
    <axis xyz="0.0 1.0 0.0"/>
    <limit effort="30" lower="0.0" upper="2.356194490192345" velocity="1.01" acceleration="1.01"/>
  </joint>
  <joint name="revolute_3" type="revolute">
    <origin rpy="0 0.7853981633974483 0" xyz="-0.2695 0.0 0.0165"/>
    <parent link="ax2_ax3_link_1"/>
    <child link="ax3_ax4_link_1"/>
    <axis xyz="0.0 1.0 0.0"/>
    <limit effort="30" lower="0.0" upper="3.141592653589793" velocity="1.01" acceleration="1.01"/>
  </joint>
  <joint name="revolute_4" type="revolute">
    <origin rpy="0 -0.7853981633974483 0" xyz="-0.2387 0.0 0.0255"/>
    <parent link="ax3_ax4_link_1"/>
    <child link="ax4_ax5_link_1"/>
    <axis xyz="0.0 1.0 0.0"/>
    <limit effort="30" lower="0.0" upper="3.141592653589793" velocity="1.01" acceleration="1.01"/>
  </joint>
  <joint name="fixed_con" type="fixed">
    <origin rpy="0 0 0" xyz="0.0 0.0 0.0"/>
    <parent link="ax4_ax5_link_1"/>
    <child link="ax4_ax5_link_2"/>
  </joint>
  <joint name="revolute_5" type="revolute">
    <origin rpy="0 0 0" xyz="0.0 0.0 0.0"/>
    <parent link="ax4_ax5_link_2"/>
    <child link="ax5_ax6_link_1"/>
    <axis xyz="1.0 0.0 0.0"/>
    <limit effort="30" lower="0.0" upper="6.283185307179586" velocity="1.01" acceleration="1.01"/>
  </joint>
  <joint name="revolute_6" type="revolute">
    <origin rpy="0 0 0" xyz="-0.163 0.0 0.0"/>
    <parent link="ax5_ax6_link_1"/>
    <child link="ax6_gripper_link_1"/>
    <axis xyz="0.0 0.0 1.0"/>
    <limit effort="30" lower="0.0" upper="3.141592653589793" velocity="1.01" acceleration="1.01"/>
  </joint>
  <joint name="fixed_gripper" type="fixed">
    <origin rpy="0 0 0" xyz="0.0 0.0 0.0"/>
    <parent link="ax6_gripper_link_1"/>
    <child link="gripper_link"/>
  </joint>
  <joint name="prismatic_1" type="prismatic">
    <origin rpy="0 0 0" xyz="0.0 0.0 0.067"/>
    <parent link="gripper_link"/>
    <child link="gripper_finger_link1"/>
    <axis xyz="0.0 1.0 0.0"/>
    <limit effort="30" lower="0.0" upper="0.05" velocity="0.1" acceleration="0.1"/>
  </joint>
  <joint name="prismatic_2" type="prismatic">
    <origin rpy="0 0 3.141592653589793" xyz="0.0 0.0 0.067"/>
    <parent link="gripper_link"/>
    <child link="gripper_finger_link2"/>
    <axis xyz="0.0 1.0 0.0"/>
    <limit effort="30" lower="0.0" upper="0.05" velocity="0.1" acceleration="0.1"/>
  </joint>
</robot>
